Workbook

Sheet Consolidado
A2: Filosofía Organizacional | B2: Liderazgo | C2: ='Filosofía Organizacional'!H8 -> 4
B3: Cultura Organizacional | C3: ='Filosofía Organizacional'!H15 -> 5
A4: Estrategias Organizacionales | B4: Proceso de Planeación Estratégica (corto, mediano y largo plazo) | C4: ='Estrategias Organizacionales'!H12 -> 3
B5: Proceso de Planeación Táctica | C5: ='Estrategias Organizacionales'!H23 -> 3.25
B6: Innovación de Productos, Procesos y Servicios | C6: ='Estrategias Organizacionales'!H28 -> 3
A7: Enfoque a Clientes, Usuarios y Mercados | B7: Inteligencia de Mercado | C7: ='Enfoque a Cl Usua y Mdos'!H10 -> 3.1428571
B8: Compromiso y Satisfacción | C8: ='Enfoque a Cl Usua y Mdos'!H18 -> 3
A9: Recursos Humanos | B9: Administración Estratégica de RRHH | C9: ='Recursos Humanos'!H5 -> 3
B10: Captación de Talento | C10: ='Recursos Humanos'!H11 -> 3.6666667
B11: Desarrollo de Talento Humano | C11: ='Recursos Humanos'!H18 -> 5
B12: Sistemas de Trabajo | C12: ='Recursos Humanos'!H25 -> 5
A13: Diseño y Desarrollo de Productos, Procesos y/o Servicios | B13: Diseño y Desarrollo de Productos, Procesos y/o Servicios | C13: ='Dis y Des de Prod Proc Servs'!H8 -> 2
A14: Procesos | B14: Control de Procesos | C14: =Procesos!H10 -> 2.5714286
B15: Administración del Conocimiento | C15: =Procesos!H18 -> 2.4
A16: Proveedores | B16: Selección y Desarrollo de Proveedores | C16: =Proveedores!H7 -> 2.5
A17: Impacto Ambiental | B17: Impacto Ambiental | C17: ='Impacto Ambiental'!H5 -> 1
A18: Factores Psicosociales | B18: Factores de Seguridad y Salud | C18: ='Factores Psicosociales'!H11 -> 4.375
B19: Factores del Desempeño en el Puesto | C19: ='Factores Psicosociales'!H19 -> 2.4
B20: Factores del Equilibrio Laboral / Familiar | C20: ='Factores Psicosociales'!H24 -> 4
B21: Factores de Carrera Laboral | C21: ='Factores Psicosociales'!H28 -> 3
A22: Resiliencia y Gestión de Entornos | B22: Resiliencia y Gestión de Entornos | C22: ='Resiliencia y Gestión Entornos'!H7 -> 1
A23: Resultados | B23: Resultados Financieros | C23: =Resultados!H7 -> 1
B24: Resultados de Clientes, Usuarios y Mercados | C24: =Resultados!H15 -> 1
B25: Resultados de Recursos Humanos | C25: =Resultados!H29 -> 1
B26: Resultados de Diseño y Desarrollo de Productos, Procesos y/o Servicios | C26: =Resultados!H35 -> 1
B27: Resultados de Procesos | C27: =Resultados!H46 -> 1
B28: Resultados de Impacto Ambiental | C28: =Resultados!H50 -> 1
B29: Resultados de Factores Psicosociales | C29: =Resultados!H54 -> 1
B30: Resultados de Resiliencia y Gestión de Entornos | C30: =Resultados!H58 -> 1
C32: =AVERAGE(C2:C30) -> 2.5622742

Sheet Filosofía Organizacional
A1: Liderazgo
B2: 1 | C2: 2 | D2: 3 | E2: 4 | F2: 5 | G2: 6
A3: a) Existe un alto involucramiento de la Dirección y Gerencia en asumir, apoyar e implementar prácticas para la calidad, la excelencia de operación, la mejora continua, la disrupción de negocio y la innovación. | E3: 4
A4: b) Las prácticas de liderazgo están implementadas en los diferentes niveles de la organización. | E4: 4
A5: c) La Dirección y Gerencia se aseguran de cumplir con los requisitos legales, normativos y regulatorios vinculados a la organización. | E5: 4
A6: d) La Dirección y Gerencia se aseguran de contribuir y/o gestionar la administración del cambio en la Organización de forma estratégica, observable, gradual y medible. | E6: 4
A7: e) La Dirección y Gerencia se aseguran de integrar y gestionar las directrices de negocio encaminadas a mantener la cadena de valor del negocio de forma sustentable. | E7: 4
B8: =SUM(B3:B7) -> 0 | C8: =SUM(C3:C7) -> 0 | D8: =SUM(D3:D7) -> 0 | E8: =SUM(E3:E7) -> 20 | F8: =SUM(F3:F7) -> 0 | G8: =SUM(G3:G7) -> 0 | H8: =SUM(B8:G8)/5 -> 4
A10: Cultura Organizacional
A11: f) Cuenta la organización con descripción de la Misión, Visión, Valores. | G11: 6
A12: g) Se enuncia, promueve y asegura el comportamiento ético en la organización (a través de por ejemplo un código de ética, o reglamento, o procedimientos, o normas). | F12: 5
A13: h) Se cuenta con prácticas generalizadas para promover la Creatividad, Innovación y la Mejora Continua en la organización. | E13: 4
A14: i) Se cuenta con mecanismos que se utilizan para obtener una comunicación efectiva en la organización. | F14: 5
B15: =SUM(B11:B14) -> 0 | C15: =SUM(C11:C14) -> 0 | D15: =SUM(D11:D14) -> 0 | E15: =SUM(E11:E14) -> 4 | F15: =SUM(F11:F14) -> 10 | G15: =SUM(G11:G14) -> 6 | H15: =SUM(B15:G15)/4 -> 5
B16: =B8+B15 -> 0 | C16: =C8+C15 -> 0 | D16: =D8+D15 -> 0 | E16: =E8+E15 -> 24 | F16: =F8+F15 -> 10 | G16: =G8+G15 -> 6 | H16: =SUM(B16:G16)/9 -> 4.4444444
H18: ¿Qué y por qué? Actividad y propósito, o alineación estratégica | I18: ¿Cómo? Descripción de Innovación (Mejora) | J18: ¿Cuándo? Año | K18: ¿Cuánto? Impacto (Indicador, $, otro) | L18: Benchmarking y/o análisis interno

Sheet Estrategias Organizacionales
A1: Proceso de Planeación Estratégica (corto, mediano y largo plazo)
B2: 1 | C2: 2 | D2: 3 | E2: 4 | F2: 5 | G2: 6
A3: a) Se cuenta con un proceso de planeación estratégica con un horizonte de al menos 3 años, contemplando diferentes escenarios de actuación con base a las variables internas y externas y se revisa anualmente. | D3: 3
A4: b) En el proceso de planeación se revisan y actualizan los elementos de la filosofía organizacional | D4: 3
A5: c) En el proceso de planeación se analiza la información sobre el sector y sus competidores principales (análisis competitivo), determinando brechas en productos y servicios en materia de precios, condiciones de venta, calidad, atributos, posibilidades de nuevos competidores y prácticas de negocio, tanto en la posición estratégica actual como en la futura de la Organización. | D5: 3
A6: d) En el proceso de planeación se integra información relativa al desempeño de la organización: mercado, análisis competitivo, calidad, servicio, financiera, recurso humano, productividad, impacto ambiental. | D6: 3
A7: e) En su proceso de planeación se incluyen las proyecciones socioeconómicas del entorno, así como las tendencias globales, al mediano y largo plazo. | D7: 3
A8: f) En su proceso de planeación se integra la información de clientes: Se tiene identificado el tamaño del mercado, su participación y evolución. | D8: 3
A9: g) En su proceso de planeación se integra la información relativa a proveedores, tales como: tendencia en precios, confiabilidad, logística, oferta, entre otros. | D9: 3
A10: h) En la organización se tienen definidos los factores clave de éxito y se les da seguimiento. | D10: 3
A11: i) En su proceso de planeación se incluye el análisis para el desarrollo de nuevos negocios (Diversificación / Disrupción). | D11: 3
B12: =SUM(B3:B11) -> 0 | C12: =SUM(C3:C11) -> 0 | D12: =SUM(D3:D11) -> 27 | E12: =SUM(E3:E11) -> 0 | F12: =SUM(F3:F11) -> 0 | G12: =SUM(G3:G11) -> 0 | H12: =SUM(B12:G12)/9 -> 3
A14: Proceso de Planeación Táctica
A15: j) A partir del proceso de planeación estratégica, la organización cuenta con prácticas utilizadas para la definición de los objetivos, metas (cuantificables) y planes de acción tácticos. | D15: 3
A16: k) Se cuenta con modelo de negocio que incluye la determinación de ingresos, egresos, capital de trabajo, cálculo de inversiones, recurso humano y en su caso requerimiento de recursos financieros. | D16: 3
A17: l) La organización cuenta con mecanismos para asegurar la efectiva ejecución de sus planes de acción tácticos y cumplimiento de metas. | E17: 4
A18: m) En la organización se promueve y se ha protegido la creación de nuevos productos, servicios y/o marcas. | E18: 4
A19: n) La organización cuenta con un mecanismo para la administración y gestión de los costos y gastos de la organización en cada uno de sus subsistemas organizacionales. | D19: 3
A20: o) La organización cuenta con un mecanismo o mejores prácticas para mejorar la eficiencia de su proceso de producción / operación. | D20: 3
A21: p) La organización cuenta con mejores prácticas para la administración y seguimiento del desempeño financiero y fiscal. | D21: 3
A22: q) La organización cuenta con mejores prácticas para la administración de inventarios / almacenes / insumos. | D22: 3
B23: =SUM(B15:B22) -> 0 | C23: =SUM(C15:C22) -> 0 | D23: =SUM(D15:D22) -> 18 | E23: =SUM(E15:E22) -> 8 | F23: =SUM(F15:F22) -> 0 | G23: =SUM(G15:G22) -> 0 | H23: =SUM(B23:G23)/8 -> 3.25
A25: Innovación de Productos, Procesos y Servicios
A26: r) La innovación de los productos, procesos y servicios está alineada a las estrategias de la organización. | D26: 3
A27: s) Se cuenta con una descripción clara de las necesidades y expectativas de los clientes, para planear la innovación de sus productos, procesos y servicios. | D27: 3
B28: =SUM(B26:B27) -> 0 | C28: =SUM(C26:C27) -> 0 | D28: =SUM(D26:D27) -> 6 | E28: =SUM(E26:E27) -> 0 | F28: =SUM(F26:F27) -> 0 | G28: =SUM(G26:G27) -> 0 | H28: =SUM(B28:G28)/2 -> 3
B29: =B12+B23+B28 -> 0 | C29: =C12+C23+C28 -> 0 | D29: =D12+D23+D28 -> 51 | E29: =E12+E23+E28 -> 8 | F29: =F12+F23+F28 -> 0 | G29: =G12+G23+G28 -> 0 | H29: =SUM(B29:G29)/19 -> 3.1052632
H31: ¿Qué y por qué? Actividad y propósito, o alineación estratégica | I31: ¿Cómo? Descripción de Innovación (Mejora) | J31: ¿Cuándo? Año | K31: ¿Cuánto? Impacto (Indicador, $, otro) | L31: Benchmarking y/o análisis interno

Sheet Enfoque a Cl Usua y Mdos
A1: Inteligencia de Mercado
B2: 1 | C2: 2 | D2: 3 | E2: 4 | F2: 5 | G2: 6
A3: a) Se tienen identificados los segmentos de mercados / clientes / servicios / rentabilidad / estratificación de la cartera de clientes a través de prácticas de Inteligencia Comercial. | D3: 3
A4: b) Se cuenta con una estrategia de mercadotecnia para atraer clientes y desarrollar nuevos mercados para posicionar a la organización en sus diferentes segmentos de mercados. | E4: 4
A5: c) Se cuenta con métodos para identificar las necesidades actuales y futuras de los diferentes segmentos de mercados / clientes / servicios / rentabilidad. Incluyendo entre otros: precios, canales de distribución, términos y condiciones de venta. | D5: 3
A6: d) La organización se asegura de cumplir con los requerimientos de los clientes / usuarios, previo a la contratación del producto y/o servicio. | D6: 3
A7: e) La organización incorpora las necesidades y/o requerimientos de los clientes / usuarios a los procesos de negocio. | D7: 3
A8: f) Se cuenta con un sistema integral de calidad enfocado a los clientes. | D8: 3
A9: g) Se cuenta con un modelo y/o mejor práctica para establecer relaciones de negocio a largo plazo con los clientes. | D9: 3
B10: =SUM(B3:B9) -> 0 | C10: =SUM(C3:C9) -> 0 | D10: =SUM(D3:D9) -> 18 | E10: =SUM(E3:E9) -> 4 | F10: =SUM(F3:F9) -> 0 | G10: =SUM(G3:G9) -> 0 | H10: =SUM(B10:G10)/7 -> 3.1428571
A12: Compromiso y Satisfacción
A13: h) Se cuenta con una descripción de los compromisos de calidad y servicio con los clientes / usuarios. | D13: 3
A14: i) Se cuenta con un proceso para conocer el grado de satisfacción de los clientes / usuarios. | D14: 3
A15: j) La organización incorpora la información de satisfacción de sus clientes / usuarios a los procesos de negocio. | D15: 3
A16: k) Se cuenta con un proceso para asegurar la recuperación de los clientes / usuarios perdidos. (Postventa / Venta Cruzada) | D16: 3
A17: l) Se cuenta con un proceso para asegurar la atención efectiva de sugerencias, quejas formales e informales. | D17: 3
B18: =SUM(B13:B17) -> 0 | C18: =SUM(C13:C17) -> 0 | D18: =SUM(D13:D17) -> 15 | E18: =SUM(E13:E17) -> 0 | F18: =SUM(F13:F17) -> 0 | G18: =SUM(G13:G17) -> 0 | H18: =SUM(B18:G18)/5 -> 3
B19: =B10+B18 -> 0 | C19: =C10+C18 -> 0 | D19: =D10+D18 -> 33 | E19: =E10+E18 -> 4 | F19: =F10+F18 -> 0 | G19: =G10+G18 -> 0 | H19: =SUM(B19:G19)/12 -> 3.0833333
H21: ¿Qué y por qué? Actividad y propósito, o alineación estratégica | I21: ¿Cómo? Descripción de Innovación (Mejora) | J21: ¿Cuándo? Año | K21: ¿Cuánto? Impacto (Indicador, $, otro) | L21: Benchmarking y/o análisis interno

Sheet Recursos Humanos
A1: Administración Estratégica de Recursos Humanos
B2: 1 | C2: 2 | D2: 3 | E2: 4 | F2: 5 | G2: 6
A3: a) Se cuenta con un Plan Estratégico de Recursos Humanos (PERH) a partir de los Objetivos Estratégicos de la Organización. | D3: 3
A4: b) Se cuentan con mejores prácticas de Recursos Humanos en: Gestión Estratégica de RRHH, Administración de RRHH, Desarrollo de RRHH, Gestión de la Productividad de RRHH, Operación de RRHH y Relaciones Laborales. | D4: 3
B5: =SUM(B3:B4) -> 0 | C5: =SUM(C3:C4) -> 0 | D5: =SUM(D3:D4) -> 6 | E5: =SUM(E3:E4) -> 0 | F5: =SUM(F3:F4) -> 0 | G5: =SUM(G3:G4) -> 0 | H5: =SUM(B5:G5)/2 -> 3
A7: Captación de Talento
A8: c) A partir del plan estratégico y del análisis de los procesos son definidos los puestos, así como sus requerimientos en toda la organización. | D8: 3
A9: d) Se cuenta con un proceso formal de captación, reclutamiento y selección y retención de talento humano alineado a los requerimientos estratégicos definidos. | E9: 4
A10: e) Se cuenta con un proceso de inducción formal para el talento humano. | E10: 4
B11: =SUM(B8:B10) -> 0 | C11: =SUM(C8:C10) -> 0 | D11: =SUM(D8:D10) -> 3 | E11: =SUM(E8:E10) -> 8 | F11: =SUM(F8:F10) -> 0 | G11: =SUM(G8:G10) -> 0 | H11: =SUM(B11:G11)/3 -> 3.6666667
A13: Desarrollo de Talento Humano
A14: f) Se cuenta con un proceso para detectar las necesidades de capacitación y desarrollo enfocadas a las estrategias de la organización. | E14: 4
A15: g) Se cuenta con programas de capacitación y desarrollo del talento humano. | E15: 4
A16: h) Se cuenta con un proceso de evaluación y/o gestión del desempeño y retroalimentación del talento humano. | G16: 6
A17: i) Se cuenta con mecanismos de reconocimiento y compensación al talento humano alineados a la evaluación del desempeño y a la productividad. | G17: 6
B18: =SUM(B14:B17) -> 0 | C18: =SUM(C14:C17) -> 0 | D18: =SUM(D14:D17) -> 0 | E18: =SUM(E14:E17) -> 8 | F18: =SUM(F14:F17) -> 0 | G18: =SUM(G14:G17) -> 12 | H18: =SUM(B18:G18)/4 -> 5
A20: Sistemas de Trabajo
A21: j) Se cuenta con métodos para promover el involucramiento del talento humano en el logro de los objetivos, tanto en forma individual como grupal. | F21: 5
A22: k) Se cuenta con prácticas para asegurar que las condiciones de trabajo sean adecuadas y acordes a normativas aplicables a su organización: seguridad e higiene industrial | F22: 5
A23: l) Se cuenta con mecanismos para evaluar la satisfacción del talento humano. | F23: 5
A24: m) Se cuenta con mecanismos que contribuyen a fomentar el bienestar del talento humano. | F24: 5
B25: =SUM(B21:B24) -> 0 | C25: =SUM(C21:C24) -> 0 | D25: =SUM(D21:D24) -> 0 | E25: =SUM(E21:E24) -> 0 | F25: =SUM(F21:F24) -> 20 | G25: =SUM(G21:G24) -> 0 | H25: =SUM(B25:G25)/4 -> 5
B26: =B5+B11+B18+B25 -> 0 | C26: =C5+C11+C18+C25 -> 0 | D26: =D5+D11+D18+D25 -> 9 | E26: =E5+E11+E18+E25 -> 16 | F26: =F5+F11+F18+F25 -> 20 | G26: =G5+G11+G18+G25 -> 12 | H26: =SUM(B26:G26)/13 -> 4.3846154
H28: ¿Qué y por qué? Actividad y propósito, o alineación estratégica | I28: ¿Cómo? Descripción de Innovación (Mejora) | J28: ¿Cuándo? Año | K28: ¿Cuánto? Impacto (Indicador, $, otro) | L28: Benchmarking y/o análisis interno

Sheet Dis y Des de Prod Proc Servs
A1: Diseño y Desarrollo de Productos, Procesos y/o Servicios
B2: 1 | C2: 2 | D2: 3 | E2: 4 | F2: 5 | G2: 6
A3: a) Se cuenta con un proceso para el diseño y modificación de productos, procesos y /o servicios. | C3: 2
A4: b) Se cuenta con mecanismos para verificar que el diseño de productos, procesos y/o servicios cumplan con los requerimientos del cliente y la normatividad aplicable previo a su liberación. | C4: 2
A5: c) Se cuenta con mecanismos para asegurar que el nuevo diseño del producto, proceso y/o servicio esté libre de fallas durante su operación. Algunos medios pueden ser: simulaciones, pruebas, prototipos, modelaciones, entre otros. | C5: 2
A6: d) Se cuenta con mecanismos para implementar y/o transferir los diseños de los productos, procesos y/o servicios a las áreas involucradas. | C6: 2
A7: e) Se cuentan con mejores prácticas para la optimización de la operación / producción a través de la definición, documentación, análisis, actualización y/o mejora y comunicación de los procesos de negocio de la empresa. | C7: 2
B8: =SUM(B3:B7) -> 0 | C8: =SUM(C3:C7) -> 10 | D8: =SUM(D3:D7) -> 0 | E8: =SUM(E3:E7) -> 0 | F8: =SUM(F3:F7) -> 0 | G8: =SUM(G3:G7) -> 0 | H8: =SUM(B8:G8)/5 -> 2
B9: =B8 -> 0 | C9: =C8 -> 10 | D9: =D8 -> 0 | E9: =E8 -> 0 | F9: =F8 -> 0 | G9: =G8 -> 0 | H9: =SUM(B9:G9)/5 -> 2
H11: ¿Qué y por qué? Actividad y propósito, o alineación estratégica | I11: ¿Cómo? Descripción de Innovación (Mejora) | J11: ¿Cuándo? Año | K11: ¿Cuánto? Impacto (Indicador, $, otro) | L11: Benchmarking y/o análisis interno

Sheet Procesos
A1: Control de Procesos
B2: 1 | C2: 2 | D2: 3 | E2: 4 | F2: 5 | G2: 6
A3: a) Se cuenta con clara definición del Macroproceso Organización incluyendo sus indicadores de desempeño. | D3: 3
A4: b) Se cuenta con clara definición de los procesos básicos en la organización incluyendo sus indicadores de desempeño. | D4: 3
A5: c) Se cuenta con un proceso establecido para el suministro, transporte, almacenaje y aprovechamiento óptimo de los insumos. | D5: 3
A6: d) Se cuenta con equipo e instalaciones adecuadas para la operación, así como un programa de mantenimiento que asegure su integridad, operación y seguridad en uso. | D6: 3
A7: e) Se cuenta con sistemas de operación que asegure: flexibilidad, minimice desperdicios y retrabajos, reduzca tiempo de ciclos, aumente la productividad del personal y activos. | C7: 2
A8: f) Se cuenta con procesos para la administración y control de la documentación de la operación, tales como: facturación, órdenes de compra, registros de operación, pólizas contables, entre otros. | C8: 2
A9: g) Se cuenta con mecanismos de control de los procesos básicos. | C9: 2
B10: =SUM(B3:B9) -> 0 | C10: =SUM(C3:C9) -> 6 | D10: =SUM(D3:D9) -> 12 | E10: =SUM(E3:E9) -> 0 | F10: =SUM(F3:F9) -> 0 | G10: =SUM(G3:G9) -> 0 | H10: =SUM(B10:G10)/7 -> 2.5714286
A12: Administración del Conocimiento
A13: h) Se utiliza la información generada por los mecanismos de control para asegurar que el desempeño de los procesos permita cumplir los requerimientos de diseño. | C13: 2
A14: i) Se cuenta con métodos para evaluar, analizar y mejorar los procesos | C14: 2
A15: j) Se cuenta con prácticas para asegurar la continuidad de los procesos en situaciones de contingencia en los que pueda verse interrumpido el proceso, producto o servicio. | C15: 2
A16: k) Se cuenta con mecanismos para mantener y proteger la información derivada de la administración y seguimiento de los procesos. | D16: 3
A17: l) Se cuenta con mecanismos para mantener y proteger el conocimiento tanto el de la operación, así como, el generado a partir de la Innovación y Mejora Continua en la organización. | D17: 3
B18: =SUM(B13:B17) -> 0 | C18: =SUM(C13:C17) -> 6 | D18: =SUM(D13:D17) -> 6 | E18: =SUM(E13:E17) -> 0 | F18: =SUM(F13:F17) -> 0 | G18: =SUM(G13:G17) -> 0 | H18: =SUM(B18:G18)/5 -> 2.4
B19: =B10+B18 -> 0 | C19: =C10+C18 -> 12 | D19: =D10+D18 -> 18 | E19: =E10+E18 -> 0 | F19: =F10+F18 -> 0 | G19: =G10+G18 -> 0 | H19: =SUM(B19:G19)/12 -> 2.5
H21: ¿Qué y por qué? Actividad y propósito, o alineación estratégica | I21: ¿Cómo? Descripción de Innovación (Mejora) | J21: ¿Cuándo? Año | K21: ¿Cuánto? Impacto (Indicador, $, otro) | L21: Benchmarking y/o análisis interno

Sheet Proveedores
A1: Selección y Desarrollo de Proveedores
B2: 1 | C2: 2 | D2: 3 | E2: 4 | F2: 5 | G2: 6
A3: a) Se cuenta con un proceso para la selección de sus proveedores basado en elementos objetivos como: confiabilidad, logística, disponibilidad y precio. | D3: 3
A4: b) Se cuenta con mecanismos para asegurar que el producto / servicio solicitado cumple con los requerimientos y especificaciones establecidas dentro de los documentos o fichas técnicas establecidas; así como en su caso, los ciclos de vida correspondientes. | D4: 3
A5: c) El proceso para evaluar y retroalimentar el desempeño de los proveedores se basa en el impacto sobre los procesos básicos. | C5: 2
A6: d) Se cuenta con prácticas en donde se involucra a los proveedores para definir proyectos orientados a mejorar la competitividad mutua. | C6: 2
B7: =SUM(B3:B6) -> 0 | C7: =SUM(C3:C6) -> 4 | D7: =SUM(D3:D6) -> 6 | E7: =SUM(E3:E6) -> 0 | F7: =SUM(F3:F6) -> 0 | G7: =SUM(G3:G6) -> 0 | H7: =SUM(B7:G7)/4 -> 2.5
B8: =B7 -> 0 | C8: =C7 -> 4 | D8: =D7 -> 6 | E8: =E7 -> 0 | F8: =F7 -> 0 | G8: =G7 -> 0 | H8: =SUM(B8:G8)/4 -> 2.5
H10: ¿Qué y por qué? Actividad y propósito, o alineación estratégica | I10: ¿Cómo? Descripción de Innovación (Mejora) | J10: ¿Cuándo? Año | K10: ¿Cuánto? Impacto (Indicador, $, otro) | L10: Benchmarking y/o análisis interno

Sheet Impacto Ambiental
A1: Impacto Ambiental
B2: 1 | C2: 2 | D2: 3 | E2: 4 | F2: 5 | G2: 6
A3: a) Se tienen identificados sus agentes contaminantes y/o responsabilidades ecológicas, derivadas de su operación. | B3: 1
A4: b) Se cuenta con procedimientos para cumplir con sus responsabilidades ecológicas y para evitar la contaminación del entorno. | B4: 1
B5: =SUM(B3:B4) -> 2 | C5: =SUM(C3:C4) -> 0 | D5: =SUM(D3:D4) -> 0 | E5: =SUM(E3:E4) -> 0 | F5: =SUM(F3:F4) -> 0 | G5: =SUM(G3:G4) -> 0 | H5: =SUM(B5:G5)/2 -> 1
B6: =B5 -> 2 | C6: =C5 -> 0 | D6: =D5 -> 0 | E6: =E5 -> 0 | F6: =F5 -> 0 | G6: =G5 -> 0 | H6: =SUM(B6:G6)/2 -> 1
H8: ¿Qué y por qué? Actividad y propósito, o alineación estratégica | I8: ¿Cómo? Descripción de Innovación (Mejora) | J8: ¿Cuándo? Año | K8: ¿Cuánto? Impacto (Indicador, $, otro) | L8: Benchmarking y/o análisis interno

Sheet Factores Psicosociales
A1: Factores de Seguridad y Salud
B2: 1 | C2: 2 | D2: 3 | E2: 4 | F2: 5 | G2: 6
A3: a) Se cuentan con procedimientos específicos para contrarrestar los efectos de acontecimientos traumáticos severos (Asaltos, accidentes, secuestros, lesiones, etc.) | F3: 5
A4: b) Se cuenta con procedimientos para identificar a los colaboradores afectados por algún acontecimiento traumático | F4: 5
A5: c) Se tienen identificados los puestos que requieren un esfuerzo físico o habilidad específica, además de que son informados a los colaboradores que los realizan desde su integración a la Organización. | F5: 4
A6: d) Se cuenta con procedimientos para evitar y actuar si existe algún riesgo de accidente en el Trabajo. | E6: 4
A7: e) Se cuenta con prácticas para fomentar una relación favorable con la comunidad Organizacional | E7: 4
A8: f) Se promueve y difunde la filosofía de la organización con la comunidad. | F8: 5
A9: g) Se cuenta con programas de prevención de violencia laboral dentro de la Organización | F9: 5
A10: h) Se cuenta con programas de prevención y promoción de la Salud dentro de la Organización | D10: 3
B11: =SUM(B3:B10) -> 0 | C11: =SUM(C3:C10) -> 0 | D11: =SUM(D3:D10) -> 3 | E11: =SUM(E3:E10) -> 8 | F11: =SUM(F3:F10) -> 24 | G11: =SUM(G3:G10) -> 0 | H11: =SUM(B11:G11)/8 -> 4.375
A13: Factores del Desempeño en el Puesto
A14: i) Se cuenta con un descriptivo de puesto, en el que los Colaboradores saben exactamente cuáles son sus funciones y métricas de desempeño esperadas. | E14: 4
A15: j) Se cuenta con procedimientos y controles para los Colaboradores que son responsables de activos de valor. | C15: 2
A16: k) Se cuenta con mejores prácticas para fomentar una relación favorable entre colaboradores y la línea de mando | C16: 2
A17: l) Se cuenta con programas de Capacitación orientados a los factores psicosociales definidos de acuerdo con las necesidades de los puestos y del entorno organizacional | C17: 2
A18: m) Se cuenta con procesos formales de medición del desempeño de cada uno de los puestos y son informados a los Colaboradores mediante una sesión de retroalimentación | C18: 2
B19: =SUM(B14:B18) -> 0 | C19: =SUM(C14:C18) -> 8 | D19: =SUM(D14:D18) -> 0 | E19: =SUM(E14:E18) -> 4 | F19: =SUM(F14:F18) -> 0 | G19: =SUM(G14:G18) -> 0 | H19: =SUM(B19:G19)/5 -> 2.4
A21: Factores del Equilibrio Laboral / Familiar
A22: n) Se cuenta con procesos o mejores prácticas relacionadas a las jornadas de trabajo (horas extra, días de descanso, días festivos) | F22: 5
A23: ñ) Se cuenta con procesos o mejores prácticas promocionadas por la Organización que contribuyan al bienestar familiar | D23: 3
B24: =SUM(B22:B23) -> 0 | C24: =SUM(C22:C23) -> 0 | D24: =SUM(D22:D23) -> 3 | E24: =SUM(E22:E23) -> 0 | F24: =SUM(F22:F23) -> 5 | G24: =SUM(G22:G23) -> 0 | H24: =SUM(B24:G24)/2 -> 4
A26: Factores de Carrera Laboral
A27: o) Se cuenta con procedimientos y/o mejores prácticas para gestionar los planes de carrera de acuerdo con la productividad individual y colectiva | D27: 3
B28: =SUM(B27:B27) -> 0 | C28: =SUM(C27:C27) -> 0 | D28: =SUM(D27:D27) -> 3 | E28: =SUM(E27:E27) -> 0 | F28: =SUM(F27:F27) -> 0 | G28: =SUM(G27:G27) -> 0 | H28: =SUM(B28:G28)/1 -> 3
B29: =B11+B19+B24+B28 -> 0 | C29: =C11+C19+C24+C28 -> 8 | D29: =D11+D19+D24+D28 -> 9 | E29: =E11+E19+E24+E28 -> 12 | F29: =F11+F19+F24+F28 -> 29 | G29: =G11+G19+G24+G28 -> 0 | H29: =SUM(B29:G29)/16 -> 3.625
H31: ¿Qué y por qué? Actividad y propósito, o alineación estratégica | I31: ¿Cómo? Descripción de Innovación (Mejora) | J31: ¿Cuándo? Año | K31: ¿Cuánto? Impacto (Indicador, $, otro) | L31: Benchmarking y/o análisis interno

Sheet Resiliencia y Gestión Entornos
A1: Resiliencia y Gestión de Entornos
B2: 1 | C2: 2 | D2: 3 | E2: 4 | F2: 5 | G2: 6
A3: a) Se cuentan con procedimientos o mejores prácticas para actuar ante entornos imprevistos, complejos, ambiguos, frágiles o acontecimientos que impliquen un cambio Organizacional disruptivo. | B3: 1
A4: b) Al encontrarse dentro de entornos imprevistos, complejos, ambiguos, frágiles o acontecimientos que impliquen un cambio Organizacional disruptivo, se cuentan con los procedimientos o mejores prácticas para determinar las mejoras y/o habilidades que necesitan los colaboradores para seguir realizando sus actividades de forma eficaz y eficiente. | B4: 1
A5: c) Al encontrarse dentro de entornos imprevistos, complejos, ambiguos, frágiles o acontecimientos que impliquen un cambio Organizacional disruptivo, se cuentan con procedimientos o mejores prácticas de contención de factores psicosociales y/ salud organizacional. | B5: 1
A6: d) Al encontrarse dentro de entornos imprevistos, complejos, ambiguos, frágiles o acontecimientos que impliquen un cambio Organizacional disruptivo, se realizan procedimientos o mejores prácticas para contener y/o fortalecer la Inteligencia Emocional de los colaboradores. | B6: 1
B7: =SUM(B3:B6) -> 4 | C7: =SUM(C3:C6) -> 0 | D7: =SUM(D3:D6) -> 0 | E7: =SUM(E3:E6) -> 0 | F7: =SUM(F3:F6) -> 0 | G7: =SUM(G3:G6) -> 0 | H7: =SUM(B7:G7)/4 -> 1
B8: =B7 -> 4 | C8: =C7 -> 0 | D8: =D7 -> 0 | E8: =E7 -> 0 | F8: =F7 -> 0 | G8: =G7 -> 0 | H8: =SUM(B8:G8)/4 -> 1
H10: ¿Qué y por qué? Actividad y propósito, o alineación estratégica | I10: ¿Cómo? Descripción de Innovación (Mejora) | J10: ¿Cuándo? Año | K10: ¿Cuánto? Impacto (Indicador, $, otro) | L10: Benchmarking y/o análisis interno

Sheet Resultados
A1: 1.- Resultados Financieros
B2: 1 | C2: 2 | D2: 3 | E2: 4 | F2: 5 | G2: 6 | I2: 1 | J2: No se tienen datos del indicador
A3: 1).- Rendimiento de Capital: Utilidad Neta / Capital Contable | B3: 1 | I3: 2 | J3: Se cuenta con datos del indicador de un año o menos
A4: 2).- Margen de Utilidad: Utilidad Neta / Ventas | B4: 1 | I4: 3 | J4: Se cuenta con datos del indicador de dos años y cumplimiento a la meta del año actual
A5: 3).- Utilidad antes de financiamientos e impuestos en números absolutos | B5: 1 | I5: 4 | J5: Se cuenta con datos de los últimos 3 años con tendencia de mejora y su análisis causal
A6: 4).- Liquidez (Efectivo + cuentas por cobrar) / pasivos circulantes | B6: 1 | I6: 5 | J6: Se cuenta con datos de los últimos 5 años con tendencia a la mejora y su análisis causal
B7: =SUM(B3:B6) -> 4 | C7: =SUM(C3:C6) -> 0 | D7: =SUM(D3:D6) -> 0 | E7: =SUM(E3:E6) -> 0 | F7: =SUM(F3:F6) -> 0 | G7: =SUM(G3:G6) -> 0 | H7: =SUM(B7:G7)/4 -> 1 | I7: 6 | J7: Se cuenta con un cumplimiento a todas las metas en los últimos 5 años, se tiene tendencia a la mejora y análisis acusal
A9: 2.- Resultados de Clientes, Usuarios y Mercados
A10: 1).- Ventas en números absolutos en volumén o niveles económicos o segmentación de rentabilidad | B10: 1
A11: 2).- Participación de mercado | B11: 1
A12: 3).- Satisfacción de clientes | B12: 1
A13: 4).- Clientes ganados / Clientes perdidos | B13: 1
A14: 5).- Costo de Garantía | B14: 1
B15: =SUM(B10:B14) -> 5 | C15: =SUM(C10:C14) -> 0 | D15: =SUM(D10:D14) -> 0 | E15: =SUM(E10:E14) -> 0 | F15: =SUM(F10:F14) -> 0 | G15: =SUM(G10:G14) -> 0 | H15: =SUM(B15:G15)/5 -> 1
A17: 3.- Resultados de Recursos Humanos
A18: 1).- Ausentismo | B18: 1
A19: 2).- Rotación | B19: 1
A20: 3).- Número de accidentes: incidentes + incapacidades | B20: 1
A21: 4).- Porcentaje de personal involucrado en proyectos de mejora | B21: 1
A22: 5).- Programa de Desarrollo (Capacitación / Planes de Carrera) | B22: 1
A23: 6).- Efectividad de los Programas de Desarrollo | B23: 1
A24: 7).- Satisfacción del Personal | B24: 1
A25: 8).- Gestión del Desempeño / Productividad | B25: 1
A26: 9).- Sistema de Compensaciones / Reconocimientos | B26: 1
A27: 10).- Relaciones Laborales | B27: 1
A28: 11).- Resultados del Liderazgo | B28: 1
B29: =SUM(B18:B28) -> 11 | C29: =SUM(C18:C28) -> 0 | D29: =SUM(D18:D28) -> 0 | E29: =SUM(E18:E28) -> 0 | F29: =SUM(F18:F28) -> 0 | G29: =SUM(G18:G28) -> 0 | H29: =SUM(B29:G29)/11 -> 1
A31: 4.- Resultados de Diseño y Desarrollo de Productos, Procesos y/o Servicios
A32: 1).- Inversión en diseño y desarrollo / ventas | B32: 1
A33: 2).- Cumplimiento de presupuesto de lanzamiento de nuevos productos en porcentaje | B33: 1
A34: 3).- Tiempo real de desarrollo de nuevos productos vs tiempo programado | B34: 1
B35: =SUM(B32:B34) -> 3 | C35: =SUM(C32:C34) -> 0 | D35: =SUM(D32:D34) -> 0 | E35: =SUM(E32:E34) -> 0 | F35: =SUM(F32:F34) -> 0 | G35: =SUM(G32:G34) -> 0 | H35: =SUM(B35:G35)/3 -> 1
A37: 5.- Resultados de Procesos
A38: 1).- Productividad: Productos o servicios realizados / Costos de la Producción - Operación | B38: 1
A39: 2).- Calidad del producto y/o servicio | B39: 1
A40: 3).- Rotación de inventario: Costo de Ventas / Inventario | B40: 1
A41: 4).- Días de Inventario: (Inventario / Costo de Ventas ) *365 | B41: 1
A42: 5).- Tiempo productivo de equipo (up time) | B42: 1
A43: 6).- Indicador de desempeño de proveedores | B43: 1
A44: 7).- Indicadores de desempeño de procesos básicos (Centrales - Soporte - Insumos - Control) | B44: 1
...
